<?xml version="1.0" encoding="utf-8"?>
<!-- This URDF was automatically created by SolidWorks to URDF Exporter! Originally created by Stephen Brawner (brawner@gmail.com) 
     Commit Version: 1.6.0-4-g7f85cfe  Build Version: 1.6.7995.38578
     For more information, please see http://wiki.ros.org/sw_urdf_exporter -->
<robot
  name="YX1">
  <link
    name="base_link">
    <inertial>
      <origin
        xyz="3.5259E-05 -1.2162E-05 0.060842"
        rpy="0 0 0" />
      <mass
        value="3.089" />
      <inertia
        ixx="0.021922"
        ixy="-7.7287E-09"
        ixz="7.1607E-08"
        iyy="0.013081"
        iyz="-8.1167E-07"
        izz="0.026484" />
    </inertial>
    <visual>
      <origin
        xyz="0 0 0"
        rpy="0 0 0" />
      <geometry>
        <mesh
          filename="package://YX1/meshes/base_link.STL" />
      </geometry>
      <material
        name="">
        <color
          rgba="0.49804 0.49804 0.49804 1" />
      </material>
    </visual>
    <collision>
      <origin
        xyz="0 0 0"
        rpy="0 0 0" />
      <geometry>
        <mesh
          filename="package://YX1/meshes/base_link.STL" />
      </geometry>
    </collision>
  </link>
  <link
    name="left_yaw_Link">
    <inertial>
      <origin
        xyz="-0.035004 -0.00045659 0.037246"
        rpy="0 0 0" />
      <mass
        value="0.39556" />
      <inertia
        ixx="0.00062021"
        ixy="1.299E-06"
        ixz="-0.00016414"
        iyy="0.00052063"
        iyz="-2.1174E-06"
        izz="0.00057596" />
    </inertial>
    <visual>
      <origin
        xyz="0 0 0"
        rpy="0 0 0" />
      <geometry>
        <mesh
          filename="package://YX1/meshes/left_yaw_Link.STL" />
      </geometry>
      <material
        name="">
        <color
          rgba="1 1 1 1" />
      </material>
    </visual>
    <collision>
      <origin
        xyz="0 0 0"
        rpy="0 0 0" />
      <geometry>
        <mesh
          filename="package://YX1/meshes/left_yaw_Link.STL" />
      </geometry>
    </collision>
  </link>
  <joint
    name="left_yaw_joint"
    type="revolute">
    <origin
      xyz="0.0 0.071324 -0.1324"
      rpy="0 0 0" />
    <parent
      link="base_link" />
    <child
      link="left_yaw_Link" />
    <axis
      xyz="0 0 1" />
    <limit
      lower="-0.43"
      upper="0.43"
      effort="20"
      velocity="20.94" />
  </joint>
  <link
    name="left_roll_Link">
    <inertial>
      <origin
        xyz="-0.0087446 0.0412 2.6491E-06"
        rpy="0 0 0" />
      <mass
        value="0.61494" />
      <inertia
        ixx="0.00067942"
        ixy="-3.8385E-05"
        ixz="1.4235E-09"
        iyy="0.00091536"
        iyz="-1.7394E-08"
        izz="0.0006494" />
    </inertial>
    <visual>
      <origin
        xyz="0 0 0"
        rpy="0 0 0" />
      <geometry>
        <mesh
          filename="package://YX1/meshes/left_roll_Link.STL" />
      </geometry>
      <material
        name="">
        <color
          rgba="1 1 1 1" />
      </material>
    </visual>
    <collision>
      <origin
        xyz="0 0 0"
        rpy="0 0 0" />
      <geometry>
        <mesh
          filename="package://YX1/meshes/left_roll_Link.STL" />
      </geometry>
    </collision>
  </link>
  <joint
    name="left_roll_joint"
    type="revolute">
    <origin
      xyz="0.033302 0 0"
      rpy="0 0 0" />
    <parent
      link="left_yaw_Link" />
    <child
      link="left_roll_Link" />
    <axis
      xyz="1 0. 0" />
    <limit
      lower="-0.32"
      upper="0.32"
      effort="33.5"
      velocity="21" />
  </joint>
  <link
    name="left_pitch_Link">
    <inertial>
      <origin
        xyz="-0.00018038 -0.001663 -0.12173"
        rpy="0 0 0" />
      <mass
        value="0.19156" />
      <inertia
        ixx="0.00030938"
        ixy="-1.5891E-07"
        ixz="-1.1828E-07"
        iyy="0.00032158"
        iyz="8.7941E-06"
        izz="3.402E-05" />
    </inertial>
    <visual>
      <origin
        xyz="0 0 0"
        rpy="0 0 0" />
      <geometry>
        <mesh
          filename="package://YX1/meshes/left_pitch_Link.STL" />
      </geometry>
      <material
        name="">
        <color
          rgba="0.49804 0.49804 0.49804 1" />
      </material>
    </visual>
    <collision>
      <origin
        xyz="0 0 0"
        rpy="0 0 0" />
      <geometry>
        <mesh
          filename="package://YX1/meshes/left_pitch_Link.STL" />
      </geometry>
    </collision>
  </link>
  <joint
    name="left_pitch_joint"
    type="revolute">
    <origin
      xyz="0 0.030959 0"
      rpy="0 0 0" />
    <parent
      link="left_roll_Link" />
    <child
      link="left_pitch_Link" />
    <axis
      xyz="-0. 1.0 0" />
    <limit
      lower="-1.57"
      upper="1.57"
      effort="20"
      velocity="20.94" />
  </joint>
  <link
    name="left_knee_Link">
    <inertial>
      <origin
        xyz="0.03159 0.00041206 -0.089451"
        rpy="0 0 0" />
      <mass
        value="0.12591" />
      <inertia
        ixx="0.00025532"
        ixy="-1.93E-07"
        ixz="1.6131E-06"
        iyy="0.00027011"
        iyz="2.1035E-08"
        izz="2.7397E-05" />
    </inertial>
    <visual>
      <origin
        xyz="0 0 0"
        rpy="0 0 0" />
      <geometry>
        <mesh
          filename="package://YX1/meshes/left_knee_Link.STL" />
      </geometry>
      <material
        name="">
        <color
          rgba="1 1 1 1" />
      </material>
    </visual>
    <collision>
      <origin
        xyz="0 0 0"
        rpy="0 0 0" />
      <geometry>
        <mesh
          filename="package://YX1/meshes/left_knee_Link.STL" />
      </geometry>
    </collision>
  </link>
  <joint
    name="left_knee_joint"
    type="revolute">
    <origin
      xyz="-0.000 -0.000 -0.29322"
      rpy="0 0 0" />
    <parent
      link="left_pitch_Link" />
    <child
      link="left_knee_Link" />
    <axis
      xyz="-0. 1.0 0" />
    <limit
      lower="-0.26"
      upper="2.05"
      effort="20"
      velocity="20.94" />
  </joint>
  <link
    name="left_ankle_Link">
    <inertial>
      <origin
        xyz="0.011062 0.0041243 -0.049762"
        rpy="0 0 0" />
      <mass
        value="0.23135" />
      <inertia
        ixx="0.00011761"
        ixy="-2.5917E-06"
        ixz="2.8721E-05"
        iyy="0.00030797"
        iyz="6.9596E-07"
        izz="0.00024974" />
    </inertial>
    <visual>
      <origin
        xyz="0 0 0"
        rpy="0 0 0" />
      <geometry>
        <mesh
          filename="package://YX1/meshes/left_ankle_Link.STL" />
      </geometry>
      <material
        name="">
        <color
          rgba="1 1 1 1" />
      </material>
    </visual>
    <collision>
      <origin
        xyz="0 0 0"
        rpy="0 0 0" />
      <geometry>
        <mesh
          filename="package://YX1/meshes/left_ankle_Link.STL" />
      </geometry>
    </collision>
  </link>
  <joint
    name="left_ankle_joint"
    type="revolute">
    <origin
      xyz="0.000 0 -0.17"
      rpy="0 0 0" />
    <parent
      link="left_knee_Link" />
    <child
      link="left_ankle_Link" />
    <axis
      xyz="0. 1. 0" />
    <limit
      lower="-0.87"
      upper="0.52"
      effort="12"
      velocity="31" />
  </joint>
  <link
    name="right_yaw_Link">
    <inertial>
      <origin
        xyz="-0.035004 0.00045659 0.037246"
        rpy="0 0 0" />
      <mass
        value="0.39556" />
      <inertia
        ixx="0.00062021"
        ixy="-1.2991E-06"
        ixz="-0.00016414"
        iyy="0.00052063"
        iyz="2.1173E-06"
        izz="0.00057596" />
    </inertial>
    <visual>
      <origin
        xyz="0 0 0"
        rpy="0 0 0" />
      <geometry>
        <mesh
          filename="package://YX1/meshes/right_yaw_Link.STL" />
      </geometry>
      <material
        name="">
        <color
          rgba="1 1 1 1" />
      </material>
    </visual>
    <collision>
      <origin
        xyz="0 0 0"
        rpy="0 0 0" />
      <geometry>
        <mesh
          filename="package://YX1/meshes/right_yaw_Link.STL" />
      </geometry>
    </collision>
  </link>
  <joint
    name="right_yaw_joint"
    type="revolute">
    <origin
      xyz="0.000 -0.071324 -0.1324"
      rpy="0 0 0" />
    <parent
      link="base_link" />
    <child
      link="right_yaw_Link" />
    <axis
      xyz="0 0 1" />
    <limit
      lower="-0.43"
      upper="0.43"
      effort="20"
      velocity="20.94" />
  </joint>
  <link
    name="right_roll_Link">
    <inertial>
      <origin
        xyz="-0.0087446 -0.0412 2.4733E-06"
        rpy="0 0 0" />
      <mass
        value="0.61494" />
      <inertia
        ixx="0.00067942"
        ixy="3.8385E-05"
        ixz="-1.4025E-09"
        iyy="0.00091536"
        iyz="-1.7386E-08"
        izz="0.0006494" />
    </inertial>
    <visual>
      <origin
        xyz="0 0 0"
        rpy="0 0 0" />
      <geometry>
        <mesh
          filename="package://YX1/meshes/right_roll_Link.STL" />
      </geometry>
      <material
        name="">
        <color
          rgba="1 1 1 1" />
      </material>
    </visual>
    <collision>
      <origin
        xyz="0 0 0"
        rpy="0 0 0" />
      <geometry>
        <mesh
          filename="package://YX1/meshes/right_roll_Link.STL" />
      </geometry>
    </collision>
  </link>
  <joint
    name="right_roll_joint"
    type="revolute">
    <origin
      xyz="0.033302 0 0"
      rpy="0 0 0" />
    <parent
      link="right_yaw_Link" />
    <child
      link="right_roll_Link" />
    <axis
      xyz="1.0 -0. 0" />
    <limit
      lower="-0.32"
      upper="0.32"
      effort="33.5"
      velocity="21" />
  </joint>
  <link
    name="right_pitch_Link">
    <inertial>
      <origin
        xyz="-0.00018121 0.0016629 -0.12173"
        rpy="0 0 0" />
      <mass
        value="0.19156" />
      <inertia
        ixx="0.00030938"
        ixy="1.5923E-07"
        ixz="-1.1118E-07"
        iyy="0.00032158"
        iyz="-8.7946E-06"
        izz="3.402E-05" />
    </inertial>
    <visual>
      <origin
        xyz="0 0 0"
        rpy="0 0 0" />
      <geometry>
        <mesh
          filename="package://YX1/meshes/right_pitch_Link.STL" />
      </geometry>
      <material
        name="">
        <color
          rgba="0.49804 0.49804 0.49804 1" />
      </material>
    </visual>
    <collision>
      <origin
        xyz="0 0 0"
        rpy="0 0 0" />
      <geometry>
        <mesh
          filename="package://YX1/meshes/right_pitch_Link.STL" />
      </geometry>
    </collision>
  </link>
  <joint
    name="right_pitch_joint"
    type="revolute">
    <origin
      xyz="0 -0.030959 0"
      rpy="0 0 0" />
    <parent
      link="right_roll_Link" />
    <child
      link="right_pitch_Link" />
    <axis
      xyz="0. 1.0 0" />
    <limit
      lower="-1.57"
      upper="1.57"
      effort="20"
      velocity="20.94" />
  </joint>
  <link
    name="right_knee_Link">
    <inertial>
      <origin
        xyz="0.03159 -0.00041205 -0.089451"
        rpy="0 0 0" />
      <mass
        value="0.12591" />
      <inertia
        ixx="0.00025532"
        ixy="1.9297E-07"
        ixz="1.6131E-06"
        iyy="0.00027011"
        iyz="-2.1031E-08"
        izz="2.7397E-05" />
    </inertial>
    <visual>
      <origin
        xyz="0 0 0"
        rpy="0 0 0" />
      <geometry>
        <mesh
          filename="package://YX1/meshes/right_knee_Link.STL" />
      </geometry>
      <material
        name="">
        <color
          rgba="1 1 1 1" />
      </material>
    </visual>
    <collision>
      <origin
        xyz="0 0 0"
        rpy="0 0 0" />
      <geometry>
        <mesh
          filename="package://YX1/meshes/right_knee_Link.STL" />
      </geometry>
    </collision>
  </link>
  <joint
    name="right_knee_joint"
    type="revolute">
    <origin
      xyz="-0.000 0. -0.29322"
      rpy="0 0 0" />
    <parent
      link="right_pitch_Link" />
    <child
      link="right_knee_Link" />
    <axis
      xyz="0. 1.0 0" />
    <limit
      lower="-0.26"
      upper="2.05"
      effort="20"
      velocity="20.94" />
  </joint>
  <link
    name="right_ankle_Link">
    <inertial>
      <origin
        xyz="0.011232 -0.0041708 -0.049762"
        rpy="0 0 0" />
      <mass
        value="0.23135" />
      <inertia
        ixx="0.0001176"
        ixy="2.3756E-06"
        ixz="2.8729E-05"
        iyy="0.00030798"
        iyz="-5.3424E-08"
        izz="0.00024974" />
    </inertial>
    <visual>
      <origin
        xyz="0 0 0"
        rpy="0 0 0" />
      <geometry>
        <mesh
          filename="package://YX1/meshes/right_ankle_Link.STL" />
      </geometry>
      <material
        name="">
        <color
          rgba="1 1 1 1" />
      </material>
    </visual>
    <collision>
      <origin
        xyz="0 0 0"
        rpy="0 0 0" />
      <geometry>
        <mesh
          filename="package://YX1/meshes/right_ankle_Link.STL" />
      </geometry>
    </collision>
  </link>
  <joint
    name="right_ankle_joint"
    type="revolute">
    <origin
      xyz="0 0 -0.17"
      rpy="0 0 0" />
    <parent
      link="right_knee_Link" />
    <child
      link="right_ankle_Link" />
    <axis
      xyz="0. 1.0 0" />
    <limit
      lower="-0.87"
      upper="0.52"
      effort="12"
      velocity="31" />
  </joint>
</robot>