<?xml version="1.0" encoding="utf-8"?>
<!-- This URDF was automatically created by SolidWorks to URDF Exporter! Originally created by Stephen Brawner (brawner@gmail.com) 
     Commit Version: 1.6.0-4-g7f85cfe  Build Version: 1.6.7995.38578
     For more information, please see http://wiki.ros.org/sw_urdf_exporter -->
<robot
  name="YX-1">
  <link
    name="base_link">
    <inertial>
      <origin
        xyz="3.52589881977561E-05 -1.21618571169921E-05 0.0608415705761093"
        rpy="0 0 0" />
      <mass
        value="3.08898899294127" />
      <inertia
        ixx="0.0219224912970811"
        ixy="-7.72865524978861E-09"
        ixz="7.16069762909807E-08"
        iyy="0.0130807934439612"
        iyz="-8.11668167240751E-07"
        izz="0.0264840545104941" />
    </inertial>
    <visual>
      <origin
        xyz="0 0 0"
        rpy="0 0 0" />
      <geometry>
        <mesh
          filename="package://YX-1/meshes/base_link.STL" />
      </geometry>
      <material
        name="">
        <color
          rgba="0.498039215686275 0.498039215686275 0.498039215686275 1" />
      </material>
    </visual>
    <collision>
      <origin
        xyz="0 0 0"
        rpy="0 0 0" />
      <geometry>
        <mesh
          filename="package://YX-1/meshes/base_link.STL" />
      </geometry>
    </collision>
  </link>
  <link
    name="left_yaw_Link">
    <inertial>
      <origin
        xyz="-0.0350037080503791 -0.000456591567301476 0.0372463735701034"
        rpy="0 0 0" />
      <mass
        value="0.395555517395699" />
      <inertia
        ixx="0.000620205903518703"
        ixy="1.29896843186358E-06"
        ixz="-0.000164142746894831"
        iyy="0.000520634597553032"
        iyz="-2.11739117204493E-06"
        izz="0.000575959612553862" />
    </inertial>
    <visual>
      <origin
        xyz="0 0 0"
        rpy="0 0 0" />
      <geometry>
        <mesh
          filename="package://YX-1/meshes/left_yaw_Link.STL" />
      </geometry>
      <material
        name="">
        <color
          rgba="1 1 1 1" />
      </material>
    </visual>
    <collision>
      <origin
        xyz="0 0 0"
        rpy="0 0 0" />
      <geometry>
        <mesh
          filename="package://YX-1/meshes/left_yaw_Link.STL" />
      </geometry>
    </collision>
  </link>
  <joint
    name="left_yaw_joint"
    type="revolute">
    <origin
      xyz="0.000 0.071324 -0.1324"
      rpy="0 0 0" />
    <parent
      link="base_link" />
    <child
      link="left_yaw_Link" />
    <axis
      xyz="0 0 1" />
    <limit
      lower="-0.43"
      upper="0.43"
      effort="20"
      velocity="20.94" />
  </joint>
  <link
    name="left_roll_Link">
    <inertial>
      <origin
        xyz="0.0490548209357755 0.0415197888784591 2.64908123400603E-06"
        rpy="0 0 0" />
      <mass
        value="0.614935433967936" />
      <inertia
        ixx="0.000679419603816697"
        ixy="-3.83852020499992E-05"
        ixz="1.42348828039911E-09"
        iyy="0.000915357380420451"
        iyz="-1.73941512323098E-08"
        izz="0.000649397167942527" />
    </inertial>
    <visual>
      <origin
        xyz="0 0 0"
        rpy="0 0 0" />
      <geometry>
        <mesh
          filename="package://YX-1/meshes/left_roll_Link.STL" />
      </geometry>
      <material
        name="">
        <color
          rgba="1 1 1 1" />
      </material>
    </visual>
    <collision>
      <origin
        xyz="0 0 0"
        rpy="0 0 0" />
      <geometry>
        <mesh
          filename="package://YX-1/meshes/left_roll_Link.STL" />
      </geometry>
    </collision>
  </link>
  <joint
    name="left_roll_joint"
    type="revolute">
    <origin
      xyz="-0.024498 -0.000 0"
      rpy="0 0 0" />
    <parent
      link="left_yaw_Link" />
    <child
      link="left_roll_Link" />
    <axis
      xyz="1 0. 0" />
    <limit
      lower="-0.32"
      upper="0.32"
      effort="33.5"
      velocity="21" />
  </joint>
  <link
    name="left_pitch_Link">
    <inertial>
      <origin
        xyz="-0.000175167874882766 0.0134604425761448 -0.121726001202457"
        rpy="0 0 0" />
      <mass
        value="0.191560909336763" />
      <inertia
        ixx="0.000309384466899546"
        ixy="-1.58911049667417E-07"
        ixz="-1.18273702367413E-07"
        iyy="0.000321577323382544"
        iyz="8.79412629086622E-06"
        izz="3.40195094387065E-05" />
    </inertial>
    <visual>
      <origin
        xyz="0 0 0"
        rpy="0 0 0" />
      <geometry>
        <mesh
          filename="package://YX-1/meshes/left_pitch_Link.STL" />
      </geometry>
      <material
        name="">
        <color
          rgba="0.498039215686275 0.498039215686275 0.498039215686275 1" />
      </material>
    </visual>
    <collision>
      <origin
        xyz="0 0 0"
        rpy="0 0 0" />
      <geometry>
        <mesh
          filename="package://YX-1/meshes/left_pitch_Link.STL" />
      </geometry>
    </collision>
  </link>
  <joint
    name="left_pitch_joint"
    type="revolute">
    <origin
      xyz="0.057794 0.016155 0"
      rpy="0 0 0" />
    <parent
      link="left_roll_Link" />
    <child
      link="left_pitch_Link" />
    <axis
      xyz="-0. 1.0 0" />
    <limit
      lower="-1.57"
      upper="1.57"
      effort="20"
      velocity="20.94" />
  </joint>
  <link
    name="left_knee_Link">
    <inertial>
      <origin
        xyz="0.0165804991795376 -0.0061062790901476 -0.0984502346022404"
        rpy="0 0 0" />
      <mass
        value="0.343457668179325" />
      <inertia
        ixx="0.000648958001306974"
        ixy="-2.59182818082286E-06"
        ixz="2.08662789533462E-05"
        iyy="0.000719817823739503"
        iyz="1.61695291664274E-06"
        izz="0.000108035679316845" />
    </inertial>
    <visual>
      <origin
        xyz="0 0 0"
        rpy="0 0 0" />
      <geometry>
        <mesh
          filename="package://YX-1/meshes/left_knee_Link.STL" />
      </geometry>
      <material
        name="">
        <color
          rgba="1 1 1 1" />
      </material>
    </visual>
    <collision>
      <origin
        xyz="0 0 0"
        rpy="0 0 0" />
      <geometry>
        <mesh
          filename="package://YX-1/meshes/left_knee_Link.STL" />
      </geometry>
    </collision>
  </link>
  <joint
    name="left_knee_joint"
    type="revolute">
    <origin
      xyz="-0.000 0.014999 -0.29322"
      rpy="0 0 0" />
    <parent
      link="left_pitch_Link" />
    <child
      link="left_knee_Link" />
    <axis
      xyz="-0. 1.0 0" />
    <limit
      lower="-0."
      upper="2.05"
      effort="20"
      velocity="20.94" />
  </joint>
  <link
    name="left_ankle_Link">
    <inertial>
      <origin
        xyz="0.0112721039303255 0.00112317679745352 -0.0497621748696437"
        rpy="0 0 0" />
      <mass
        value="0.231347089996303" />
      <inertia
        ixx="0.000117606919596764"
        ixy="-2.59166971451289E-06"
        ixz="2.8720704816765E-05"
        iyy="0.000307973388516554"
        iyz="6.95956113893796E-07"
        izz="0.000249737250704842" />
    </inertial>
    <visual>
      <origin
        xyz="0 0 0"
        rpy="0 0 0" />
      <geometry>
        <mesh
          filename="package://YX-1/meshes/left_ankle_Link.STL" />
      </geometry>
      <material
        name="">
        <color
          rgba="1 1 1 1" />
      </material>
    </visual>
    <collision>
      <origin
        xyz="0 0 0"
        rpy="0 0 0" />
      <geometry>
        <mesh
          filename="package://YX-1/meshes/left_ankle_Link.STL" />
      </geometry>
    </collision>
  </link>
  <joint
    name="left_ankle_joint"
    type="revolute">
    <origin
      xyz="0.036954 0.000 -0.226"
      rpy="0 0 0" />
    <parent
      link="left_knee_Link" />
    <child
      link="left_ankle_Link" />
    <axis
      xyz="0. 1. 0" />
    <limit
      lower="-0.87"
      upper="0.52"
      effort="12"
      velocity="31" />
  </joint>
  <link
    name="right_yaw_Link">
    <inertial>
      <origin
        xyz="-0.0350037081688261 0.000456591333932558 0.0372463737519437"
        rpy="0 0 0" />
      <mass
        value="0.395555520464489" />
      <inertia
        ixx="0.000620205896565006"
        ixy="-1.29910907708401E-06"
        ixz="-0.000164142746450215"
        iyy="0.000520634592407249"
        iyz="2.11734091953231E-06"
        izz="0.000575959618213611" />
    </inertial>
    <visual>
      <origin
        xyz="0 0 0"
        rpy="0 0 0" />
      <geometry>
        <mesh
          filename="package://YX-1/meshes/right_yaw_Link.STL" />
      </geometry>
      <material
        name="">
        <color
          rgba="1 1 1 1" />
      </material>
    </visual>
    <collision>
      <origin
        xyz="0 0 0"
        rpy="0 0 0" />
      <geometry>
        <mesh
          filename="package://YX-1/meshes/right_yaw_Link.STL" />
      </geometry>
    </collision>
  </link>
  <joint
    name="right_yaw_joint"
    type="revolute">
    <origin
      xyz="0.000 -0.071324 -0.1324"
      rpy="0 0 0" />
    <parent
      link="base_link" />
    <child
      link="right_yaw_Link" />
    <axis
      xyz="0 0 1" />
    <limit
      lower="-0.43"
      upper="0.43"
      effort="20"
      velocity="20.94" />
  </joint>
  <link
    name="right_roll_Link">
    <inertial>
      <origin
        xyz="0.049054834658441 -0.0415197890574546 2.47325582666824E-06"
        rpy="0 0 0" />
      <mass
        value="0.61493543396794" />
      <inertia
        ixx="0.000679419566639"
        ixy="3.83852029639554E-05"
        ixz="-1.40248579421081E-09"
        iyy="0.000915357380402942"
        iyz="-1.73858240682049E-08"
        izz="0.000649397205137738" />
    </inertial>
    <visual>
      <origin
        xyz="0 0 0"
        rpy="0 0 0" />
      <geometry>
        <mesh
          filename="package://YX-1/meshes/right_roll_Link.STL" />
      </geometry>
      <material
        name="">
        <color
          rgba="1 1 1 1" />
      </material>
    </visual>
    <collision>
      <origin
        xyz="0 0 0"
        rpy="0 0 0" />
      <geometry>
        <mesh
          filename="package://YX-1/meshes/right_roll_Link.STL" />
      </geometry>
    </collision>
  </link>
  <joint
    name="right_roll_joint"
    type="revolute">
    <origin
      xyz="-0.024498 0.000 0"
      rpy="0 0 0" />
    <parent
      link="right_yaw_Link" />
    <child
      link="right_roll_Link" />
    <axis
      xyz="1.0 -0. 0" />
    <limit
      lower="-0.32"
      upper="0.32"
      effort="33.5"
      velocity="21" />
  </joint>
  <link
    name="right_pitch_Link">
    <inertial>
      <origin
        xyz="-0.00017599416070248 -0.0134604890978961 -0.121725978273735"
        rpy="0 0 0" />
      <mass
        value="0.191560880366818" />
      <inertia
        ixx="0.000309384476776972"
        ixy="1.59229089346011E-07"
        ixz="-1.11180201651207E-07"
        iyy="0.000321577313248357"
        iyz="-8.79462487797804E-06"
        izz="3.40195124396643E-05" />
    </inertial>
    <visual>
      <origin
        xyz="0 0 0"
        rpy="0 0 0" />
      <geometry>
        <mesh
          filename="package://YX-1/meshes/right_pitch_Link.STL" />
      </geometry>
      <material
        name="">
        <color
          rgba="0.498039215686275 0.498039215686275 0.498039215686275 1" />
      </material>
    </visual>
    <collision>
      <origin
        xyz="0 0 0"
        rpy="0 0 0" />
      <geometry>
        <mesh
          filename="package://YX-1/meshes/right_pitch_Link.STL" />
      </geometry>
    </collision>
  </link>
  <joint
    name="right_pitch_joint"
    type="revolute">
    <origin
      xyz="0.057794 -0.016155 0"
      rpy="0 0 0" />
    <parent
      link="right_roll_Link" />
    <child
      link="right_pitch_Link" />
    <axis
      xyz="0. 1.0 0" />
    <limit
      lower="-1.57"
      upper="1.57"
      effort="20"
      velocity="20.94" />
  </joint>
  <link
    name="right_knee_Link">
    <inertial>
      <origin
        xyz="0.016555009805745 0.00415228094848838 -0.0986051277840649"
        rpy="0 0 0" />
      <mass
        value="0.343457675133855" />
      <inertia
        ixx="0.00064887135205594"
        ixy="-7.29118771975222E-07"
        ixz="1.94750783918288E-05"
        iyy="0.000719904486990651"
        iyz="1.0905276061046E-06"
        izz="0.00010803568489468" />
    </inertial>
    <visual>
      <origin
        xyz="0 0 0"
        rpy="0 0 0" />
      <geometry>
        <mesh
          filename="package://YX-1/meshes/right_knee_Link.STL" />
      </geometry>
      <material
        name="">
        <color
          rgba="1 1 1 1" />
      </material>
    </visual>
    <collision>
      <origin
        xyz="0 0 0"
        rpy="0 0 0" />
      <geometry>
        <mesh
          filename="package://YX-1/meshes/right_knee_Link.STL" />
      </geometry>
    </collision>
  </link>
  <joint
    name="right_knee_joint"
    type="revolute">
    <origin
      xyz="-0.000 -0.014999 -0.29322"
      rpy="0 0 0" />
    <parent
      link="right_pitch_Link" />
    <child
      link="right_knee_Link" />
    <axis
      xyz="0. 1.0 0" />
    <limit
      lower="-0."
      upper="2.05"
      effort="20"
      velocity="20.94" />
  </joint>
  <link
    name="right_ankle_Link">
    <inertial>
      <origin
        xyz="0.0112714795919435 -0.00117105353124788 -0.0497621746296486"
        rpy="0 0 0" />
      <mass
        value="0.231347096509017" />
      <inertia
        ixx="0.000117601285625093"
        ixy="2.37563889317818E-06"
        ixz="2.87290884249692E-05"
        iyy="0.000307979035082662"
        iyz="-5.34240202821934E-08"
        izz="0.000249737263074448" />
    </inertial>
    <visual>
      <origin
        xyz="0 0 0"
        rpy="0 0 0" />
      <geometry>
        <mesh
          filename="package://YX-1/meshes/right_ankle_Link.STL" />
      </geometry>
      <material
        name="">
        <color
          rgba="1 1 1 1" />
      </material>
    </visual>
    <collision>
      <origin
        xyz="0 0 0"
        rpy="0 0 0" />
      <geometry>
        <mesh
          filename="package://YX-1/meshes/right_ankle_Link.STL" />
      </geometry>
    </collision>
  </link>
  <joint
    name="right_ankle_joint"
    type="revolute">
    <origin
      xyz="0.036954 -0.00 -0.226"
      rpy="0 0 0" />
    <parent
      link="right_knee_Link" />
    <child
      link="right_ankle_Link" />
    <axis
      xyz="0. 1.0 0" />
    <limit
      lower="-0.87"
      upper="0.52"
      effort="12"
      velocity="31" />
  </joint>
</robot>